Workbook
Name A1_Empresa: Empresas_[Nombre Empresa]
Name A2_Bancos: Listas!$A$2:$A$23
Name A3_Documento: Listas!$B$2:$B$6

Sheet Formulario
B1: N° Operación | E1: Formulario de Rendición de Caja chica, Fondos por rendir, Reembolso de gastos 2026 | Z1: Cuenta no usa concepto
Z2: Centro no usa partida
B3: N° Req.
B5: * Uso exclusivo Control Pagos
A7: Tipo de rendición
A11: FALSE | D11: FALSE | H11: FALSE | J11: Número de Fondo por rendir
A13: Información del responsable
A15: Nombre Responsable | J15: Rut
A17: Cargo | J17: Teléfono / Cel
A19: Empresa | J19: Fecha
A22: Tipo de Cuenta | G22: N° Cuenta | J22: Banco
A24: Información de la rendición
A27: Tipo de Doc. | B27: Fecha | C27: N° Doc | D27: Descripción | H27: Centro de Responsabilidad | I27: Cuenta Contable | J27: Partida | L27: Clasificación | M27: Monto ($)
N28: =A28&"|"&I28&"|"&J28&"|"&L28 | Z28: =+VLOOKUP(H28,'2. Centros'!J:K,2,0)
N29: =A29&"|"&I29&"|"&J29&"|"&L29 | Z29: =+VLOOKUP(H29,'2. Centros'!J:K,2,0)
N30: =A30&"|"&I30&"|"&J30&"|"&L30 | Z30: =+VLOOKUP(H30,'2. Centros'!J:K,2,0)
N31: =A31&"|"&I31&"|"&J31&"|"&L31 | Z31: =+VLOOKUP(H31,'2. Centros'!J:K,2,0)
N32: =A32&"|"&I32&"|"&J32&"|"&L32 | Z32: =+VLOOKUP(H32,'2. Centros'!J:K,2,0)
N33: =A33&"|"&I33&"|"&J33&"|"&L33 | Z33: =+VLOOKUP(H33,'2. Centros'!J:K,2,0)
N34: =A34&"|"&I34&"|"&J34&"|"&L34 | Z34: =+VLOOKUP(H34,'2. Centros'!J:K,2,0)
N35: =A35&"|"&I35&"|"&J35&"|"&L35 | Z35: =+VLOOKUP(H35,'2. Centros'!J:K,2,0)
N36: =A36&"|"&I36&"|"&J36&"|"&L36 | Z36: =+VLOOKUP(H36,'2. Centros'!J:K,2,0)
N37: =A37&"|"&I37&"|"&J37&"|"&L37 | Z37: =+VLOOKUP(H37,'2. Centros'!J:K,2,0)
N38: =A38&"|"&I38&"|"&J38&"|"&L38 | Z38: =+VLOOKUP(H38,'2. Centros'!J:K,2,0)
N39: =A39&"|"&I39&"|"&J39&"|"&L39 | Z39: =+VLOOKUP(H39,'2. Centros'!J:K,2,0)
... N42: =A42&"|"&I42&"|"&J42&"|"&L42 | Z42: =+VLOOKUP(H42,'2. Centros'!J:K,2,0)
H43: Total | M43: =SUM(M28:M41,M58:M85) | Z43: =+VLOOKUP(H43,'2. Centros'!J:K,2,0)
H44: (-) Anticipos | Z44: =+VLOOKUP(H44,'2. Centros'!J:K,2,0)
H45: Total Boletas y Facturas | M45: =+M43+M44 | Z45: =+VLOOKUP(H45,'2. Centros'!J:K,2,0)
Z46: =+VLOOKUP(H46,'2. Centros'!J:K,2,0)
Z47: =+VLOOKUP(H47,'2. Centros'!J:K,2,0)
B48: Firma Responsable del Fondo o Caja | H48: Firma Aprobador | L48: Firma Control Pagos | Z48: =+VLOOKUP(H48,'2. Centros'!J:K,2,0)
E49: Formulario de Rendición de Caja chica, Fondos por rendir, Reembolso de gastos 2026 (Hoja 2) | Z49: =+VLOOKUP(H49,'2. Centros'!J:K,2,0)
Z50: =+VLOOKUP(H50,'2. Centros'!J:K,2,0)
Z51: =+VLOOKUP(H51,'2. Centros'!J:K,2,0)
Z52: =+VLOOKUP(H52,'2. Centros'!J:K,2,0)
Z53: =+VLOOKUP(H53,'2. Centros'!J:K,2,0)
Z54: =+VLOOKUP(H54,'2. Centros'!J:K,2,0)
Z55: =+VLOOKUP(H55,'2. Centros'!J:K,2,0)
Z56: =+VLOOKUP(H56,'2. Centros'!J:K,2,0)
...
